<?xml version="1.0" encoding="utf-8"?>
<!-- =================================================================================== -->
<!-- |    This document was autogenerated by xacro from curio.urdf.xacro               | -->
<!-- |    EDITING THIS FILE BY HAND IS NOT RECOMMENDED                                 | -->
<!-- =================================================================================== -->
<!-- 
    Software License Agreement (BSD-3-Clause)

    Copyright (c) 2019 Rhys Mainwaring
    All rights reserved.

    Redistribution and use in source and binary forms, with or without
    modification, are permitted provided that the following conditions
    are met:

    1.  Redistributions of source code must retain the above copyright
        notice, this list of conditions and the following disclaimer.

    2.  Redistributions in binary form must reproduce the above
        copyright notice, this list of conditions and the following
        disclaimer in the documentation and/or other materials provided
        with the distribution.

    3.  Neither the name of the copyright holder nor the names of its
        contributors may be used to endorse or promote products derived
        from this software without specific prior written permission.

    THIS SOFTWARE IS PROVIDED BY THE COPYRIGHT HOLDERS AND CONTRIBUTORS
    "AS IS" AND ANY EXPRESS OR IMPLIED WARRANTIES, INCLUDING, BUT NOT
    LIMITED TO, THE IMPLIED WARRANTIES OF MERCHANTABILITY AND FITNESS
    FOR A PARTICULAR PURPOSE ARE DISCLAIMED. IN NO EVENT SHALL THE
    COPYRIGHT HOLDER OR CONTRIBUTORS BE LIABLE FOR ANY DIRECT, INDIRECT,
    INCIDENTAL, SPECIAL, EXEMPLARY, OR CONSEQUENTIAL DAMAGES (INCLUDING,
    BUT NOT LIMITED TO, PROCUREMENT OF SUBSTITUTE GOODS OR SERVICES;
    LOSS OF USE, DATA, OR PROFITS; OR BUSINESS INTERRUPTION) HOWEVER
    CAUSED AND ON ANY THEORY OF LIABILITY, WHETHER IN CONTRACT, STRICT
    LIABILITY, OR TORT (INCLUDING NEGLIGENCE OR OTHERWISE) ARISING IN
    ANY WAY OUT OF THE USE OF THIS SOFTWARE, EVEN IF ADVISED OF THE
    POSSIBILITY OF SUCH DAMAGE.
-->
<!-- Robot description for Curio, a Sawppy Rover robot.

 -->
<robot name="curio" xmlns:xacro="http://ros.org/wiki/xacro">
  <material name="red">
    <color rgba="0.8 0 0 1"/>
  </material>
  <material name="green">
    <color rgba="0 0.8 0 1"/>
  </material>
  <material name="blue">
    <color rgba="0 0 0.8 1"/>
  </material>
  <material name="orange">
    <color rgba="0.8 0.25 0 1"/>
  </material>
  <material name="black">
    <color rgba="0 0 0 1"/>
  </material>
  <material name="dark_gray">
    <color rgba="0.5 0.5 0.5 1"/>
  </material>
  <material name="gray">
    <color rgba="0.753 0.753 0.753 1"/>
  </material>
  <material name="silver">
    <color rgba="0.88 0.88 0.88 1"/>
  </material>
  <material name="white">
    <color rgba="1 1 1 1"/>
  </material>
  <!-- Gazebo plugins -->
  <gazebo>
    <!-- ROS Control 

            Resources:
                https://answers.ros.org/question/292444/gazebo_ros_control-plugin-gazeboroscontrolplugin-missing-legacymodens-defaultrobothwsim/
        -->
    <plugin filename="libgazebo_ros_control.so" name="gazebo_ros_control">
      <robotNamespace>/</robotNamespace>
      <robotSimType>gazebo_ros_control/DefaultRobotHWSim</robotSimType>
      <legacyModeNS>false</legacyModeNS>
    </plugin>
    <!-- Publish state of passive joints
        
            Resources:
                http://answers.gazebosim.org/question/13844/getting-joint-angles-for-passive-urdf-model/
         -->
    <plugin filename="libgazebo_ros_joint_state_publisher.so" name="gazebo_ros_joint_state_publisher">
      <robotNamespace>/</robotNamespace>
      <jointName>
                left_rocker_joint, right_rocker_joint,
                front_left_corner_joint, front_right_corner_joint,
                front_left_wheel_joint, front_right_wheel_joint,
                left_bogie_joint, right_bogie_joint,
                mid_left_wheel_joint, mid_right_wheel_joint,
                back_left_corner_joint, back_right_corner_joint,
                back_left_wheel_joint, back_right_wheel_joint
            </jointName>
      <updateRate>50</updateRate>
      <alwaysOn>true</alwaysOn>
    </plugin>
  </gazebo>
  <!-- The base link - the reference link for the entire model -->
  <link name="base_link">
    <visual>
      <origin rpy="0 0 0" xyz="0 0 0"/>
      <geometry>
        <box size="0.001 0.001 0.001"/>
      </geometry>
      <material name="orange"/>
    </visual>
    <collision>
      <origin rpy="0 0 0" xyz="0 0 0"/>
      <geometry>
        <box size="0.001 0.001 0.001"/>
      </geometry>
    </collision>
    <inertial>
      <mass value="0.01"/>
      <inertia ixx="0.01" ixy="0" ixz="0" iyy="0.01" iyz="0" izz="0.01"/>
    </inertial>
  </link>
  <gazebo reference="base_link">
    <material>Gazebo/Orange</material>
  </gazebo>
  <link name="body_box_link">
    <visual>
      <origin rpy="0 0 0" xyz="0 0 0"/>
      <geometry>
        <box size="0.425 0.285 0.093"/>
      </geometry>
      <material name="dark_gray"/>
    </visual>
    <collision>
      <origin rpy="0 0 0" xyz="0 0 0"/>
      <geometry>
        <box size="0.425 0.285 0.093"/>
      </geometry>
    </collision>
    <inertial>
      <origin rpy="0 0 0" xyz="0 0 0"/>
      <mass value="0.5"/>
      <inertia ixx="0.00374475" ixy="0.0" ixz="0.0" iyy="0.00788641666667" iyz="0.0" izz="0.0109104166667"/>
    </inertial>
  </link>
  <gazebo reference="body_box_link">
    <material>Gazebo/DarkGray</material>
  </gazebo>
  <joint name="body_box_joint" type="fixed">
    <origin rpy="0 0 0" xyz="0 0 0"/>
    <parent link="base_link"/>
    <child link="body_box_link"/>
  </joint>
  <gazebo reference="body_box_joint">
    <disableFixedJointLumping>true</disableFixedJointLumping>
    <preserveFixedJoint>true</preserveFixedJoint>
  </gazebo>
  <!-- TODO: Implementing the differential is tricky
    
        URDF does not support closed loops in the robot description,
        on the other hand SDF for Gazebo does.
    -->
  <link name="diff_brace_link">
    <visual>
      <origin rpy="0 0 1.57079632679" xyz="0 0 0"/>
      <geometry>
        <box size="0.200 0.015 0.015"/>
      </geometry>
      <material name="dark_gray"/>
    </visual>
    <collision>
      <origin rpy="0 0 1.57079632679" xyz="0 0 0"/>
      <geometry>
        <box size="0.200 0.015 0.015"/>
      </geometry>
    </collision>
    <inertial>
      <origin rpy="0 0 1.57079632679" xyz="0 0 0"/>
      <mass value="0.1"/>
      <inertia ixx="3.75e-06" ixy="0.0" ixz="0.0" iyy="0.000335208333333" iyz="0.0" izz="0.000335208333333"/>
    </inertial>
  </link>
  <gazebo reference="diff_brace_link">
    <material>Gazebo/DarkGray</material>
  </gazebo>
  <joint name="diff_brace_joint" type="continuous">
    <origin rpy="0 0 0" xyz="0 0 0.0681"/>
    <axis xyz="0 0 1"/>
    <parent link="base_link"/>
    <child link="diff_brace_link"/>
  </joint>
  <gazebo reference="diff_brace_joint">
    <provideFeedback>true</provideFeedback>
  </gazebo>
  <!-- Gazebo only links & joints connecting the differential brace to the rockers -->
  <gazebo>
    <link name="left_turnbuckle_link">
      <visual name="left_turnbuckle_link_visual">
        <geometry>
          <box>
            <size>0.07 0.005 0.005</size>
          </box>
        </geometry>
      </visual>
      <collision name="left_turnbuckle_link_collision">
        <geometry>
          <box>
            <size>0.07 0.005 0.005</size>
          </box>
        </geometry>
      </collision>
      <inertial>
        <mass>0.01</mass>
        <inertia>
          <ixx>0.0001</ixx>
          <ixy>0</ixy>
          <ixz>0</ixz>
          <iyy>0.0001</iyy>
          <iyz>0</iyz>
          <izz>0.0001</izz>
        </inertia>
      </inertial>
    </link>
    <joint name="left_turnbuckle_rocker_joint" type="ball">
      <pose>0 0 0 0 0 0</pose>
      <parent>left_rocker_link</parent>
      <child>left_turnbuckle_link</child>
    </joint>
    <!-- <joint name="left_turnbuckle_diff_joint" type="ball">
            <pose>0 0.170 0 0 0 0</pose>
            <parent>diff_brace_link</parent> 
            <child>left_turnbuckle_link</child> 
        </joint> -->
    <link name="right_turnbuckle_link">
      <visual name="right_turnbuckle_link_visual">
        <geometry>
          <box>
            <size>0.07 0.005 0.005</size>
          </box>
        </geometry>
      </visual>
      <collision name="right_turnbuckle_link_collision">
        <geometry>
          <box>
            <size>0.07 0.005 0.005</size>
          </box>
        </geometry>
      </collision>
      <inertial>
        <mass>0.01</mass>
        <inertia>
          <ixx>0.0001</ixx>
          <ixy>0</ixy>
          <ixz>0</ixz>
          <iyy>0.0001</iyy>
          <iyz>0</iyz>
          <izz>0.0001</izz>
        </inertia>
      </inertial>
    </link>
    <joint name="right_turnbuckle_rocker_joint" type="ball">
      <pose>0 0 0 0 0 0</pose>
      <parent>right_rocker_link</parent>
      <child>right_turnbuckle_link</child>
    </joint>
    <!-- <joint name="right_turnbuckle_diff_joint" type="ball">
            <pose>0 -0.170 0 0 0 0</pose>
            <parent>diff_brace_link</parent> 
            <child>right_turnbuckle_link</child> 
        </joint> -->
  </gazebo>
  <link name="left_rocker_link">
    <visual>
      <origin rpy="0 0 0" xyz="0 0 0"/>
      <geometry>
        <box size="0.1 0.015 0.015"/>
      </geometry>
      <material name="dark_gray"/>
    </visual>
    <collision>
      <origin rpy="0 0 0" xyz="0 0 0"/>
      <geometry>
        <box size="0.1 0.015 0.015"/>
      </geometry>
    </collision>
    <inertial>
      <origin rpy="0 0 0" xyz="0 0 0"/>
      <mass value="0.1"/>
      <inertia ixx="3.75e-06" ixy="0.0" ixz="0.0" iyy="8.52083333333e-05" iyz="0.0" izz="8.52083333333e-05"/>
    </inertial>
  </link>
  <gazebo reference="left_rocker_link">
    <material>Gazebo/DarkGray</material>
  </gazebo>
  <link name="right_rocker_link">
    <visual>
      <origin rpy="0 0 0" xyz="0 0 0"/>
      <geometry>
        <box size="0.1 0.015 0.015"/>
      </geometry>
      <material name="dark_gray"/>
    </visual>
    <collision>
      <origin rpy="0 0 0" xyz="0 0 0"/>
      <geometry>
        <box size="0.1 0.015 0.015"/>
      </geometry>
    </collision>
    <inertial>
      <origin rpy="0 0 0" xyz="0 0 0"/>
      <mass value="0.1"/>
      <inertia ixx="3.75e-06" ixy="0.0" ixz="0.0" iyy="8.52083333333e-05" iyz="0.0" izz="8.52083333333e-05"/>
    </inertial>
  </link>
  <gazebo reference="right_rocker_link">
    <material>Gazebo/DarkGray</material>
  </gazebo>
  <joint name="left_rocker_joint" type="continuous">
    <origin rpy="0 0 0" xyz="0.071 0.154 0.0118"/>
    <axis xyz="0 1 0"/>
    <parent link="base_link"/>
    <child link="left_rocker_link"/>
  </joint>
  <gazebo reference="left_rocker_joint">
    <provideFeedback>true</provideFeedback>
  </gazebo>
  <joint name="right_rocker_joint" type="continuous">
    <origin rpy="0 0 0" xyz="0.071 -0.154 0.0118"/>
    <axis xyz="0 1 0"/>
    <parent link="base_link"/>
    <child link="right_rocker_link"/>
  </joint>
  <gazebo reference="right_rocker_joint">
    <provideFeedback>true</provideFeedback>
  </gazebo>
  <link name="front_left_corner_link">
    <visual>
      <origin rpy="0 0 0" xyz="0 0 0"/>
      <geometry>
        <box size="0.1 0.1 0.1"/>
      </geometry>
      <material name="dark_gray"/>
    </visual>
    <collision>
      <origin rpy="0 0 0" xyz="0 0 0"/>
      <geometry>
        <box size="0.1 0.1 0.1"/>
      </geometry>
    </collision>
    <inertial>
      <origin rpy="0 0 0" xyz="0 0 0"/>
      <mass value="0.1"/>
      <inertia ixx="0.000166666666667" ixy="0.0" ixz="0.0" iyy="0.000166666666667" iyz="0.0" izz="0.000166666666667"/>
    </inertial>
  </link>
  <gazebo reference="front_left_corner_link">
    <material>Gazebo/DarkGray</material>
  </gazebo>
  <link name="front_right_corner_link">
    <visual>
      <origin rpy="0 0 0" xyz="0 0 0"/>
      <geometry>
        <box size="0.1 0.1 0.1"/>
      </geometry>
      <material name="dark_gray"/>
    </visual>
    <collision>
      <origin rpy="0 0 0" xyz="0 0 0"/>
      <geometry>
        <box size="0.1 0.1 0.1"/>
      </geometry>
    </collision>
    <inertial>
      <origin rpy="0 0 0" xyz="0 0 0"/>
      <mass value="0.1"/>
      <inertia ixx="0.000166666666667" ixy="0.0" ixz="0.0" iyy="0.000166666666667" iyz="0.0" izz="0.000166666666667"/>
    </inertial>
  </link>
  <gazebo reference="front_right_corner_link">
    <material>Gazebo/DarkGray</material>
  </gazebo>
  <joint name="front_left_corner_joint" type="continuous">
    <origin rpy="0 0 0" xyz="0.2116 0.081 -0.0279"/>
    <axis xyz="0 0 1"/>
    <parent link="left_rocker_link"/>
    <child link="front_left_corner_link"/>
  </joint>
  <gazebo reference="front_left_corner_joint">
    <provideFeedback>true</provideFeedback>
  </gazebo>
  <joint name="front_right_corner_joint" type="continuous">
    <origin rpy="0 0 0" xyz="0.2116 -0.081 -0.0279"/>
    <axis xyz="0 0 1"/>
    <parent link="right_rocker_link"/>
    <child link="front_right_corner_link"/>
  </joint>
  <gazebo reference="front_right_corner_joint">
    <provideFeedback>true</provideFeedback>
  </gazebo>
  <link name="front_left_wheel_link">
    <visual>
      <origin rpy="1.57079632679 0 0" xyz="0 0 0"/>
      <geometry>
        <mesh filename="package://curio_description/meshes/wheels/wheel.stl"/>
      </geometry>
      <material name="dark_gray"/>
    </visual>
    <collision>
      <origin rpy="1.57079632679 0 0" xyz="0 0 0"/>
      <geometry>
        <cylinder length="0.1" radius="0.06"/>
      </geometry>
    </collision>
    <inertial>
      <origin rpy="0 0 0" xyz="0 0 0"/>
      <mass value="0.1"/>
      <inertia ixx="0.000173333333333" ixy="0.0" ixz="0.0" iyy="0.000173333333333" iyz="0.0" izz="0.00018"/>
    </inertial>
  </link>
  <gazebo reference="front_left_wheel_link">
    <material>Gazebo/DarkGray</material>
  </gazebo>
  <link name="front_right_wheel_link">
    <visual>
      <origin rpy="-1.57079632679 0 0" xyz="0 0 0"/>
      <geometry>
        <mesh filename="package://curio_description/meshes/wheels/wheel.stl"/>
      </geometry>
      <material name="dark_gray"/>
    </visual>
    <collision>
      <origin rpy="-1.57079632679 0 0" xyz="0 0 0"/>
      <geometry>
        <cylinder length="0.1" radius="0.06"/>
      </geometry>
    </collision>
    <inertial>
      <origin rpy="0 0 0" xyz="0 0 0"/>
      <mass value="0.1"/>
      <inertia ixx="0.000173333333333" ixy="0.0" ixz="0.0" iyy="0.000173333333333" iyz="0.0" izz="0.00018"/>
    </inertial>
  </link>
  <gazebo reference="front_right_wheel_link">
    <material>Gazebo/DarkGray</material>
  </gazebo>
  <joint name="front_left_wheel_joint" type="continuous">
    <origin rpy="0 0 0" xyz="0 0 -0.132"/>
    <axis xyz="0 1 0"/>
    <parent link="front_left_corner_link"/>
    <child link="front_left_wheel_link"/>
  </joint>
  <gazebo reference="front_left_wheel_joint">
    <provideFeedback>true</provideFeedback>
  </gazebo>
  <joint name="front_right_wheel_joint" type="continuous">
    <origin rpy="0 0 0" xyz="0 0 -0.132"/>
    <axis xyz="0 1 0"/>
    <parent link="front_right_corner_link"/>
    <child link="front_right_wheel_link"/>
  </joint>
  <gazebo reference="front_right_wheel_joint">
    <provideFeedback>true</provideFeedback>
  </gazebo>
  <link name="left_bogie_link">
    <visual>
      <origin rpy="0 0 0" xyz="0 0 0"/>
      <geometry>
        <box size="0.1 0.015 0.015"/>
      </geometry>
      <material name="dark_gray"/>
    </visual>
    <collision>
      <origin rpy="0 0 0" xyz="0 0 0"/>
      <geometry>
        <box size="0.1 0.015 0.015"/>
      </geometry>
    </collision>
    <inertial>
      <origin rpy="0 0 0" xyz="0 0 0"/>
      <mass value="0.1"/>
      <inertia ixx="3.75e-06" ixy="0.0" ixz="0.0" iyy="8.52083333333e-05" iyz="0.0" izz="8.52083333333e-05"/>
    </inertial>
  </link>
  <gazebo reference="left_bogie_link">
    <material>Gazebo/DarkGray</material>
  </gazebo>
  <link name="right_bogie_link">
    <visual>
      <origin rpy="0 0 0" xyz="0 0 0"/>
      <geometry>
        <box size="0.1 0.015 0.015"/>
      </geometry>
      <material name="dark_gray"/>
    </visual>
    <collision>
      <origin rpy="0 0 0" xyz="0 0 0"/>
      <geometry>
        <box size="0.1 0.015 0.015"/>
      </geometry>
    </collision>
    <inertial>
      <origin rpy="0 0 0" xyz="0 0 0"/>
      <mass value="0.1"/>
      <inertia ixx="3.75e-06" ixy="0.0" ixz="0.0" iyy="8.52083333333e-05" iyz="0.0" izz="8.52083333333e-05"/>
    </inertial>
  </link>
  <gazebo reference="right_bogie_link">
    <material>Gazebo/DarkGray</material>
  </gazebo>
  <joint name="left_bogie_joint" type="continuous">
    <origin rpy="0 0 0" xyz="-0.181 0.0675 -0.062"/>
    <axis xyz="0 1 0"/>
    <parent link="left_rocker_link"/>
    <child link="left_bogie_link"/>
  </joint>
  <gazebo reference="left_bogie_joint">
    <provideFeedback>true</provideFeedback>
  </gazebo>
  <joint name="right_bogie_joint" type="continuous">
    <origin rpy="0 0 0" xyz="-0.181 -0.0675 -0.062"/>
    <axis xyz="0 1 0"/>
    <parent link="right_rocker_link"/>
    <child link="right_bogie_link"/>
  </joint>
  <gazebo reference="right_bogie_joint">
    <provideFeedback>true</provideFeedback>
  </gazebo>
  <link name="mid_left_wheel_link">
    <visual>
      <origin rpy="1.57079632679 0 0" xyz="0 0 0"/>
      <geometry>
        <mesh filename="package://curio_description/meshes/wheels/wheel.stl"/>
      </geometry>
      <material name="dark_gray"/>
    </visual>
    <collision>
      <origin rpy="1.57079632679 0 0" xyz="0 0 0"/>
      <geometry>
        <cylinder length="0.1" radius="0.06"/>
      </geometry>
    </collision>
    <inertial>
      <origin rpy="0 0 0" xyz="0 0 0"/>
      <mass value="0.1"/>
      <inertia ixx="0.000173333333333" ixy="0.0" ixz="0.0" iyy="0.000173333333333" iyz="0.0" izz="0.00018"/>
    </inertial>
  </link>
  <gazebo reference="mid_left_wheel_link">
    <material>Gazebo/DarkGray</material>
  </gazebo>
  <link name="mid_right_wheel_link">
    <visual>
      <origin rpy="-1.57079632679 0 0" xyz="0 0 0"/>
      <geometry>
        <mesh filename="package://curio_description/meshes/wheels/wheel.stl"/>
      </geometry>
      <material name="dark_gray"/>
    </visual>
    <collision>
      <origin rpy="-1.57079632679 0 0" xyz="0 0 0"/>
      <geometry>
        <cylinder length="0.1" radius="0.06"/>
      </geometry>
    </collision>
    <inertial>
      <origin rpy="0 0 0" xyz="0 0 0"/>
      <mass value="0.1"/>
      <inertia ixx="0.000173333333333" ixy="0.0" ixz="0.0" iyy="0.000173333333333" iyz="0.0" izz="0.00018"/>
    </inertial>
  </link>
  <gazebo reference="mid_right_wheel_link">
    <material>Gazebo/DarkGray</material>
  </gazebo>
  <joint name="mid_left_wheel_joint" type="continuous">
    <origin rpy="0 0 0" xyz="0.1063 0.0929 -0.0959"/>
    <axis xyz="0 1 0"/>
    <parent link="left_bogie_link"/>
    <child link="mid_left_wheel_link"/>
  </joint>
  <gazebo reference="mid_left_wheel_joint">
    <provideFeedback>true</provideFeedback>
  </gazebo>
  <joint name="mid_right_wheel_joint" type="continuous">
    <origin rpy="0 0 0" xyz="0.1063 -0.0929 -0.0959"/>
    <axis xyz="0 1 0"/>
    <parent link="right_bogie_link"/>
    <child link="mid_right_wheel_link"/>
  </joint>
  <gazebo reference="mid_right_wheel_joint">
    <provideFeedback>true</provideFeedback>
  </gazebo>
  <link name="back_left_corner_link">
    <visual>
      <origin rpy="0 0 0" xyz="0 0 0"/>
      <geometry>
        <box size="0.1 0.1 0.1"/>
      </geometry>
      <material name="dark_gray"/>
    </visual>
    <collision>
      <origin rpy="0 0 0" xyz="0 0 0"/>
      <geometry>
        <box size="0.1 0.1 0.1"/>
      </geometry>
    </collision>
    <inertial>
      <origin rpy="0 0 0" xyz="0 0 0"/>
      <mass value="0.1"/>
      <inertia ixx="0.000166666666667" ixy="0.0" ixz="0.0" iyy="0.000166666666667" iyz="0.0" izz="0.000166666666667"/>
    </inertial>
  </link>
  <gazebo reference="back_left_corner_link">
    <material>Gazebo/DarkGray</material>
  </gazebo>
  <link name="back_right_corner_link">
    <visual>
      <origin rpy="0 0 0" xyz="0 0 0"/>
      <geometry>
        <box size="0.1 0.1 0.1"/>
      </geometry>
      <material name="dark_gray"/>
    </visual>
    <collision>
      <origin rpy="0 0 0" xyz="0 0 0"/>
      <geometry>
        <box size="0.1 0.1 0.1"/>
      </geometry>
    </collision>
    <inertial>
      <origin rpy="0 0 0" xyz="0 0 0"/>
      <mass value="0.1"/>
      <inertia ixx="0.000166666666667" ixy="0.0" ixz="0.0" iyy="0.000166666666667" iyz="0.0" izz="0.000166666666667"/>
    </inertial>
  </link>
  <gazebo reference="back_right_corner_link">
    <material>Gazebo/DarkGray</material>
  </gazebo>
  <joint name="back_left_corner_joint" type="continuous">
    <origin rpy="0 0 0" xyz="-0.149 0.0136 0.0338"/>
    <axis xyz="0 0 1"/>
    <parent link="left_bogie_link"/>
    <child link="back_left_corner_link"/>
  </joint>
  <gazebo reference="back_left_corner_joint">
    <provideFeedback>true</provideFeedback>
  </gazebo>
  <joint name="back_right_corner_joint" type="continuous">
    <origin rpy="0 0 0" xyz="-0.149 -0.0136 0.0338"/>
    <axis xyz="0 0 1"/>
    <parent link="right_bogie_link"/>
    <child link="back_right_corner_link"/>
  </joint>
  <gazebo reference="back_right_corner_joint">
    <provideFeedback>true</provideFeedback>
  </gazebo>
  <link name="back_left_wheel_link">
    <visual>
      <origin rpy="1.57079632679 0 0" xyz="0 0 0"/>
      <geometry>
        <mesh filename="package://curio_description/meshes/wheels/wheel.stl"/>
      </geometry>
      <material name="dark_gray"/>
    </visual>
    <collision>
      <origin rpy="1.57079632679 0 0" xyz="0 0 0"/>
      <geometry>
        <cylinder length="0.1" radius="0.06"/>
      </geometry>
    </collision>
    <inertial>
      <origin rpy="0 0 0" xyz="0 0 0"/>
      <mass value="0.1"/>
      <inertia ixx="0.000173333333333" ixy="0.0" ixz="0.0" iyy="0.000173333333333" iyz="0.0" izz="0.00018"/>
    </inertial>
  </link>
  <gazebo reference="back_left_wheel_link">
    <material>Gazebo/DarkGray</material>
  </gazebo>
  <link name="back_right_wheel_link">
    <visual>
      <origin rpy="-1.57079632679 0 0" xyz="0 0 0"/>
      <geometry>
        <mesh filename="package://curio_description/meshes/wheels/wheel.stl"/>
      </geometry>
      <material name="dark_gray"/>
    </visual>
    <collision>
      <origin rpy="-1.57079632679 0 0" xyz="0 0 0"/>
      <geometry>
        <cylinder length="0.1" radius="0.06"/>
      </geometry>
    </collision>
    <inertial>
      <origin rpy="0 0 0" xyz="0 0 0"/>
      <mass value="0.1"/>
      <inertia ixx="0.000173333333333" ixy="0.0" ixz="0.0" iyy="0.000173333333333" iyz="0.0" izz="0.00018"/>
    </inertial>
  </link>
  <gazebo reference="back_right_wheel_link">
    <material>Gazebo/DarkGray</material>
  </gazebo>
  <joint name="back_left_wheel_joint" type="continuous">
    <origin rpy="0 0 0" xyz="0 0 -0.132"/>
    <axis xyz="0 1 0"/>
    <parent link="back_left_corner_link"/>
    <child link="back_left_wheel_link"/>
  </joint>
  <gazebo reference="back_left_wheel_joint">
    <provideFeedback>true</provideFeedback>
  </gazebo>
  <joint name="back_right_wheel_joint" type="continuous">
    <origin rpy="0 0 0" xyz="0 0 -0.132"/>
    <axis xyz="0 1 0"/>
    <parent link="back_right_corner_link"/>
    <child link="back_right_wheel_link"/>
  </joint>
  <gazebo reference="back_right_wheel_joint">
    <provideFeedback>true</provideFeedback>
  </gazebo>
</robot>
